Workbook

Sheet Cover & Summary
A1: LARSEN & TOUBRO LIMITED (L&T)
A2: FINANCIAL STATEMENT ANALYSIS & VALUATION (FSAV) MASTER MODEL
A4: 1. EXECUTIVE SUMMARY & METADATA
A5: Company Name | B5: Larsen & Toubro Limited
A6: NSE Symbol | B6: LT
A7: BSE Code | B7: 500510
A8: Sector / Industry | B8: Infrastructure, Heavy Engineering & Technology Services
A9: Current Share Price (Rs.) | B9: 3600
A10: Outstanding Shares (Cr) | B10: 275.13
A11: Market Capitalization (Rs. Cr) | B11: =B9*B10 -> 990468
A13: 2. CAPITAL STRUCTURE SUMMARY (as at 31 Mar 2026)
A14: Component | B14: Amount (Rs. Cr) | C14: % of Total Capital
A15: Total Debt | B15: ='Balance Sheet'!F47 -> 159535.37 | C15: =B15/B17 -> 0.55381567
A16: Total Equity | B16: ='Balance Sheet'!F10 -> 128530.46 | C16: =B16/B17 -> 0.44618433
A17: Total Capital Employed | B17: =B15+B16 -> 288065.83 | C17: 1
A19: 3. VALUATION SUMMARY
A20: Methodology | B20: Implied Share Price (Rs.) | C20: Implied Upside / (Downside) %
A21: DCF Valuation (Base Case) | B21: ='DCF Valuation'!B26 -> 2426.4045 | C21: =(B21-B9)/B9 -> -0.32599875
A22: Comparable Valuation (Median EV/EBITDA) | B22: ='Comparable Valuation'!B24 -> 3059.1152 | C22: =(B22-B9)/B9 -> -0.15024577
A24: 4. WORKBOOK SITEMAP & TAB INDEX
A25: Tab Name | B25: Description
A26: Cover & Summary | B26: Executive summary, company metadata, capital structure, and sitemap
A27: Assumptions & Drivers | B27: Master model drivers: growth rates, operating costs %, WC days, CapEx %, WACC, and DCF parameters
A28: Income Statement | B28: 10-Year Income Statement (FY22-FY26 Historical + FY27F-FY31F Forecast)
A29: Balance Sheet | B29: 10-Year Balance Sheet (FY22-FY26 Historical + FY27F-FY31F Forecast)
A30: Cash Flow Statement | B30: 10-Year Cash Flow Statement (FY22-FY26 Historical + FY27F-FY31F Forecast)
A31: WC & PPE Schedule | B31: Working Capital Days, Trade Receivables/Inventories/Payables schedule, and PPE/CapEx schedule
A32: Common-size & Trend | B32: Common-size Income Statement (% Rev), Balance Sheet (% Assets), and YoY Trend %
A33: Ratio Analysis | B33: Liquidity, Profitability, Efficiency, Solvency, and Market Ratios across 5 historical years
A34: Beta Calculation | B34: Weekly returns regression, stock price beta, and Blume adjustment relative to NIFTY 50
A35: Capital Structure & WACC | B35: CAPM Cost of Equity, Cost of Debt, Capital Weights, and WACC schedule
A36: DCF Valuation | B36: FCFF projections, Present Value, Terminal Value, Enterprise Value, Equity Value, and Intrinsic Value
... A39: Football Field | B39: Valuation Summary Field comparing DCF, Comps, and 52-Week Price Range

Sheet Assumptions & Drivers
A1: ASSUMPTIONS & DRIVERS
A3: Parameter | B3: Value | C3: Rationale & Explanation
A4: A. GROWTH ASSUMPTIONS
A5: Revenue Growth - Base Case | B5: 0.12 | C5: Based on L&T current record order book of Rs. 4.75+ Lakh Cr & 5-Yr historical CAGR (~16.2%)
A6: Revenue Growth - Best Case | B6: 0.15 | C6: Assumes accelerated execution across domestic mega-infra, Middle East hydrocarbon EPC & green energy
A7: Revenue Growth - Worst Case | B7: 0.09 | C7: Considers supply chain disruptions, geopolitical headwinds, and delayed client milestone billings
A8: B. OPERATING COST ASSUMPTIONS (% of Revenue)
A9: Operating & Direct Expenses % | B9: 0.535 | C9: Raw material, subcontracting, and construction costs modeled at realistic 3-year historical average (~53.5%)
A10: Employee Benefit Expenses % | B10: 0.18 | C10: Employee costs modeled at historical average (~18.0% of revenue) reflecting engineering & IT staff
A11: Other Expenses % | B11: 0.04 | C11: Other corporate & administrative expenses forecast at 4.0% of revenue in line with operational efficiencies
A12: Other Income (% of Revenue) | B12: 0.02 | C12: Other non-operating income assumed at historical average of ~2.0% of operational revenue
A13: Effective Tax Rate | B13: 0.25 | C13: Effective corporate income tax rate modeled at 25.0%
A14: Marginal Tax Rate | B14: 0.2517 | C14: Standard Indian corporate statutory tax rate of 25.17% (22% + 10% surcharge + 4% cess)
A15: C. WORKING CAPITAL DAYS
A16: Receivable Days | B16: 77 | C16: Based on 5-year historical average trade receivable days (~77 days)
A17: Inventory Days | B17: 12 | C17: Reflects inventory holding days for construction materials and spares (~12 days)
A18: Payable Days | B18: 86 | C18: Based on historical vendor & subcontractor payable settlement cycle (~86 days)
A19: D. CAPEX & DEPRECIATION
A20: Capex (% of Revenue) | B20: 0.045 | C20: Capital expenditure projected at 4.5% of annual revenue supporting green hydrogen, data centers & machinery renewal
A21: Depreciation Rate (% of Opening Net PPE) | B21: 0.28 | C21: Depreciation rate on opening net fixed assets modeled at 28.0% based on Ind AS useful asset lives
A22: E. CAPITAL STRUCTURE & DEBT
A23: Target Debt Weight | B23: 0.3 | C23: Long-term target debt capital weight set at 30.0%
A24: Target Equity Weight | B24: 0.7 | C24: Target equity capital weight set at 70.0%
A25: Borrowing Growth Rate (% per year) | B25: 0.08 | C25: Annual expansion of credit facilities and project debt (8.0% p.a.) to fund order book expansion
A26: Pre-Tax Cost of Debt | B26: 0.078 | C26: Weighted average pre-tax cost of borrowing estimated at 7.80% based on existing bond coupon rates
A27: F. WACC PARAMETERS
A28: Risk-Free Rate (Rf) | B28: 0.071 | C28: Based on current yield of 10-Year Government of India Benchmark Bond (~7.10%)
A29: Equity Risk Premium (ERP) | B29: 0.06 | C29: Standard equity risk premium for Indian equity market (6.00%)
A30: G. DCF PARAMETERS
A31: Terminal Growth Rate (g) | B31: 0.05 | C31: Long-term terminal growth rate modeled at 5.00% matching long-term Indian GDP growth
A32: Dividend Payout Ratio | B32: 0.4 | C32: Dividend payout assumed at 40.0% of PAT in line with L&T capital return and dividend track record

Sheet Income Statement
A1: CONSOLIDATED INCOME STATEMENT (INR Crores)
A3: Particulars | B3: FY22 | C3: FY23 | D3: FY24 | E3: FY25 | F3: FY26 | G3: FY27F | H3: FY28F | I3: FY29F | J3: FY30F | K3: FY31F
A4: INCOME
A5: Revenue from Operations | B5: 156521.23 | C5: 183340.7 | D5: 221112.89 | E5: 255734.45 | F5: 285874.36 | G5: =F5*(1+'Assumptions & Drivers'!$B$5) -> 320179.28 | H5: =G5*(1+'Assumptions & Drivers'!$B$5) -> 358600.8 | I5: =H5*(1+'Assumptions & Drivers'!$B$5) -> 401632.89 | J5: =I5*(1+'Assumptions & Drivers'!$B$5) -> 449828.84 | K5: =J5*(1+'Assumptions & Drivers'!$B$5) -> 503808.3
A6: Other Income | B6: 2267.08 | C6: 2942.23 | D6: 3450.12 | E6: 4124.82 | F6: 5760.68 | G6: =G5*'Assumptions & Drivers'!$B$12 -> 6403.5857 | H6: =H5*'Assumptions & Drivers'!$B$12 -> 7172.0159 | I6: =I5*'Assumptions & Drivers'!$B$12 -> 8032.6579 | J6: =J5*'Assumptions & Drivers'!$B$12 -> 8996.5768 | K6: =K5*'Assumptions & Drivers'!$B$12 -> 10076.166
A7: Total Revenue | B7: =B5+B6 -> 158788.31 | C7: =C5+C6 -> 186282.93 | D7: =D5+D6 -> 224563.01 | E7: =E5+E6 -> 259859.27 | F7: =F5+F6 -> 291635.04 | G7: =G5+G6 -> 326582.87 | H7: =H5+H6 -> 365772.81 | I7: =I5+I6 -> 409665.55 | ... K7: =K5+K6 -> 513884.47
A8: EXPENSES
A9: Operating and Direct Expenses | B9: 82346.02 | C9: 100770.8 | D9: 117282.3 | E9: 137579.9 | F9: 153724.81 | G9: =G5*'Assumptions & Drivers'!$B$9 -> 171295.92 | H9: =H5*'Assumptions & Drivers'!$B$9 -> 191851.43 | I9: =I5*'Assumptions & Drivers'!$B$9 -> 214873.6 | J9: =J5*'Assumptions & Drivers'!$B$9 -> 240658.43 | K9: =K5*'Assumptions & Drivers'!$B$9 -> 269537.44
A10: Employee Benefit Expenses | B10: 29733.53 | C10: 36200.4 | D10: 41500.6 | E10: 46768.68 | F10: 52187.22 | G10: =G5*'Assumptions & Drivers'!$B$10 -> 57632.271 | H10: =H5*'Assumptions & Drivers'!$B$10 -> 64548.143 | I10: =I5*'Assumptions & Drivers'!$B$10 -> 72293.921 | J10: =J5*'Assumptions & Drivers'!$B$10 -> 80969.191 | K10: =K5*'Assumptions & Drivers'!$B$10 -> 90685.494
A11: Finance Costs | B11: 3125.7 | C11: 3200.1 | D11: 3250.4 | E11: 3334.37 | F11: 2848.82 | G11: =(('Balance Sheet'!F47+'Balance Sheet'!G47)/2)*'Assumptions & Drivers'!$B$26 -> 12941.509 | H11: =(('Balance Sheet'!G47+'Balance Sheet'!H47)/2)*'Assumptions & Drivers'!$B$26 -> 13976.83 | I11: =(('Balance Sheet'!H47+'Balance Sheet'!I47)/2)*'Assumptions & Drivers'!$B$26 -> 15094.976 | J11: =(('Balance Sheet'!I47+'Balance Sheet'!J47)/2)*'Assumptions & Drivers'!$B$26 -> 16302.574 | K11: =(('Balance Sheet'!J47+'Balance Sheet'!K47)/2)*'Assumptions & Drivers'!$B$26 -> 17606.78
A12: Depreciation and Amortisation | B12: 2947.95 | C12: 3502.4 | D12: 3810.5 | E12: 4121.18 | F12: 4364.75 | G12: ='WC & PPE Schedule'!G19 -> 11617.808 | H12: ='WC & PPE Schedule'!H19 -> 12399.08 | I12: ='WC & PPE Schedule'!I19 -> 13445.708 | J12: ='WC & PPE Schedule'!J19 -> 14741.484 | K12: ='WC & PPE Schedule'!K19 -> 16281.712
A13: Other Expenses | B13: 8831.89 | C13: 9450.2 | D13: 10200.3 | E13: 11558.13 | F13: 11699.45 | G13: =G5*'Assumptions & Drivers'!$B$11 -> 12807.171 | H13: =H5*'Assumptions & Drivers'!$B$11 -> 14344.032 | I13: =I5*'Assumptions & Drivers'!$B$11 -> 16065.316 | J13: =J5*'Assumptions & Drivers'!$B$11 -> 17993.154 | K13: =K5*'Assumptions & Drivers'!$B$11 -> 20152.332
A14: Total Expenses | B14: =SUM(B9:B13) -> 126985.09 | C14: =SUM(C9:C13) -> 153123.9 | D14: =SUM(D9:D13) -> 176044.1 | E14: =SUM(E9:E13) -> 203362.26 | F14: =SUM(F9:F13) -> 224825.05 | G14: =SUM(G9:G13) -> 266294.68 | H14: =SUM(H9:H13) -> 297119.51 | I14: =SUM(I9:I13) -> 331773.52 | ... K14: =SUM(K9:K13) -> 414263.76
A15: Profit Before Exceptional Items and Tax | B15: =B7-B14 -> 31803.22 | C15: =C7-C14 -> 33159.03 | D15: =D7-D14 -> 48518.91 | E15: =E7-E14 -> 56497.01 | F15: =F7-F14 -> 66809.99 | G15: =G7-G14 -> 60288.193 | H15: =H7-H14 -> 68653.301 | I15: =I7-I14 -> 77892.032 | ... K15: =K7-K14 -> 99620.707
A16: Exceptional Items | B16: 0 | C16: -95.4 | D16: 112.5 | E16: 474.78 | F16: -1722.44 | G16: 0 | H16: 0 | I16: 0 | J16: 0 | K16: 0
A17: Profit Before Tax | B17: =B15+B16 -> 31803.22 | C17: =C15+C16 -> 33063.63 | D17: =D15+D16 -> 48631.41 | E17: =E15+E16 -> 56971.79 | F17: =F15+F16 -> 65087.55 | G17: =G15+G16 -> 60288.193 | H17: =H15+H16 -> 68653.301 | I17: =I15+I16 -> 77892.032 | ... K17: =K15+K16 -> 99620.707
A18: Current Tax | B18: 4512.09 | C18: 4980.2 | D18: 5520.4 | E18: 6100.82 | F18: 6752.96 | G18: =G17*'Assumptions & Drivers'!$B$13 -> 15072.048 | H18: =H17*'Assumptions & Drivers'!$B$13 -> 17163.325 | I18: =I17*'Assumptions & Drivers'!$B$13 -> 19473.008 | J18: =J17*'Assumptions & Drivers'!$B$13 -> 22040.146 | K18: =K17*'Assumptions & Drivers'!$B$13 -> 24905.177
A19: Deferred Tax | B19: -295.48 | C19: -120.3 | D19: -180.5 | E19: -209.42 | F19: 63.45 | G19: 0 | H19: 0 | I19: 0 | J19: 0 | K19: 0
A20: Total Tax Expenses | B20: =B18+B19 -> 4216.61 | C20: =C18+C19 -> 4859.9 | D20: =D18+D19 -> 5339.9 | E20: =E18+E19 -> 5891.4 | F20: =F18+F19 -> 6816.41 | G20: =G18+G19 -> 15072.048 | H20: =H18+H19 -> 17163.325 | I20: =I18+I19 -> 19473.008 | ... K20: =K18+K19 -> 24905.177
A21: Profit After Tax (before MI) | B21: =B17-B20 -> 27586.61 | C21: =C17-C20 -> 28203.73 | D21: =D17-D20 -> 43291.51 | E21: =E17-E20 -> 51080.39 | F21: =F17-F20 -> 58271.14 | G21: =G17-G20 -> 45216.145 | H21: =H17-H20 -> 51489.976 | I21: =I17-I20 -> 58419.024 | ... K21: =K17-K20 -> 74715.53
A22: Minority Interest | B22: 185.4 | C22: -45.2 | D22: -12.3 | E22: -14.06 | F22: -205.52 | G22: 0 | H22: 0 | I22: 0 | J22: 0 | K22: 0
A23: Consolidated PAT (attributable to owners) | B23: =B21-B22 -> 27401.21 | C23: =C21-C22 -> 28248.93 | D23: =D21-D22 -> 43303.81 | E23: =E21-E22 -> 51094.45 | F23: =F21-F22 -> 58476.66 | G23: =G21-G22 -> 45216.145 | H23: =H21-H22 -> 51489.976 | I23: =I21-I22 -> 58419.024 | ... K23: =K21-K22 -> 74715.53
A24: EBITDA (derived) | B24: =B5-B9-B10-B13 -> 35609.79 | C24: =C5-C9-C10-C13 -> 36919.3 | D24: =D5-D9-D10-D13 -> 52129.69 | E24: =E5-E9-E10-E13 -> 59827.74 | F24: =F5-F9-F10-F13 -> 68262.88 | G24: =G5-G9-G10-G13 -> 78443.924 | H24: =H5-H9-H10-H13 -> 87857.195 | I24: =I5-I9-I10-I13 -> 98400.059 | ... K24: =K5-K9-K10-K13 -> 123433.03
A25: EBIT (derived) | B25: =B24-B12 -> 32661.84 | C25: =C24-C12 -> 33416.9 | D25: =D24-D12 -> 48319.19 | E25: =E24-E12 -> 55706.56 | F25: =F24-F12 -> 63898.13 | G25: =G24-G12 -> 66826.117 | H25: =H24-H12 -> 75458.115 | I25: =I24-I12 -> 84954.351 | ... K25: =K24-K12 -> 107151.32
A26: Basic EPS (Rs.) | B26: 60.45 | C26: 74.5 | D26: 92.8 | E26: 124.5 | F26: 137.8 | G26: =G23/'Cover & Summary'!$B$10 -> 164.34465 | H26: =H23/'Cover & Summary'!$B$10 -> 187.14781 | I26: =I23/'Cover & Summary'!$B$10 -> 212.33244 | J26: =J23/'Cover & Summary'!$B$10 -> 240.32435 | K26: =K23/'Cover & Summary'!$B$10 -> 271.56446
A27: Diluted EPS (Rs.) | B27: 60.38 | C27: 74.42 | D27: 92.71 | E27: 124.42 | F27: 137.72 | G27: =G26 -> 164.34465 | H27: =H26 -> 187.14781 | I27: =I26 -> 212.33244 | J27: =J26 -> 240.32435 | K27: =K26 -> 271.56446
A28: Equity Dividend (Cr) | B28: 2520.4 | C28: 3080.5 | D28: 3920.6 | E28: 4900.2 | F28: 5600.4 | G28: =G23*'Assumptions & Drivers'!$B$32 -> 18086.458 | H28: =H23*'Assumptions & Drivers'!$B$32 -> 20595.99 | I28: =I23*'Assumptions & Drivers'!$B$32 -> 23367.61 | J28: =J23*'Assumptions & Drivers'!$B$32 -> 26448.175 | K28: =K23*'Assumptions & Drivers'!$B$32 -> 29886.212
A29: EBITDA Margin % (chart helper) | B29: =B24/B5 -> 0.22750773 | C29: =C24/C5 -> 0.20136991 | D29: =D24/D5 -> 0.23576052 | E29: =E24/E5 -> 0.23394478 | F29: =F24/F5 -> 0.2387863 | G29: =G24/G5 -> 0.245 | H29: =H24/H5 -> 0.245 | I29: =I24/I5 -> 0.245 | ... K29: =K24/K5 -> 0.245

Sheet Balance Sheet
A1: CONSOLIDATED BALANCE SHEET (INR Crores)
A3: Particulars | B3: FY22 | C3: FY23 | D3: FY24 | E3: FY25 | F3: FY26 | G3: FY27F | H3: FY28F | I3: FY29F | J3: FY30F | K3: FY31F
A4: EQUITY & LIABILITIES
A5: Equity Share Capital | B5: 281.01 | C5: 281.1 | D5: 274.93 | E5: 275.04 | F5: 275.13 | G5: =F5 -> 275.13 | H5: =G5 -> 275.13 | I5: =H5 -> 275.13 | J5: =I5 -> 275.13 | K5: =J5 -> 275.13
A6: Total Share Capital (incl. preference) | B6: 281.01 | C6: 281.1 | D6: 274.93 | E6: 275.04 | F6: 275.13 | G6: =F6 -> 275.13 | H6: =G6 -> 275.13 | I6: =H6 -> 275.13 | J6: =I6 -> 275.13 | K6: =J6 -> 275.13
A7: Reserves and Surplus | B7: 82126.65 | C7: 89044.85 | D7: 86084.31 | E7: 97380.56 | F7: 109014.67 | G7: =F7+'Income Statement'!G23-'Income Statement'!G28 -> 136144.36 | H7: =G7+'Income Statement'!H23-'Income Statement'!H28 -> 167038.34 | I7: =H7+'Income Statement'!I23-'Income Statement'!I28 -> 202089.76 | J7: =I7+'Income Statement'!J23-'Income Statement'!J28 -> 241762.02 | K7: =J7+'Income Statement'!K23-'Income Statement'!K28 -> 286591.34
A8: Total Shareholders' Funds | B8: =B6+B7 -> 82407.66 | C8: =C6+C7 -> 89325.95 | D8: =D6+D7 -> 86359.24 | E8: =E6+E7 -> 97655.6 | F8: =F6+F7 -> 109289.8 | G8: =G6+G7 -> 136419.49 | H8: =H6+H7 -> 167313.47 | I8: =I6+I7 -> 202364.89 | ... K8: =K6+K7 -> 286866.47
A9: Minority Interest | B9: 12966.07 | C9: 14241.27 | D9: 16190.42 | E9: 17748.08 | F9: 19240.66 | G9: =F9 -> 19240.66 | H9: =G9 -> 19240.66 | I9: =H9 -> 19240.66 | J9: =I9 -> 19240.66 | K9: =J9 -> 19240.66
A10: Total Equity | B10: =B8+B9 -> 95373.73 | C10: =C8+C9 -> 103567.22 | D10: =D8+D9 -> 102549.66 | E10: =E8+E9 -> 115403.68 | F10: =F8+F9 -> 128530.46 | G10: =G8+G9 -> 155660.15 | H10: =H8+H9 -> 186554.13 | I10: =I8+I9 -> 221605.55 | ... K10: =K8+K9 -> 306107.13
A11: NON-CURRENT LIABILITIES
A12: Long Term Borrowings | B12: 63363.29 | C12: 63136.95 | D12: 58337.82 | E12: 60020.76 | F12: 68485.5 | G12: =F12*(1+'Assumptions & Drivers'!$B$25) -> 73964.34 | H12: =G12*(1+'Assumptions & Drivers'!$B$25) -> 79881.487 | I12: =H12*(1+'Assumptions & Drivers'!$B$25) -> 86272.006 | J12: =I12*(1+'Assumptions & Drivers'!$B$25) -> 93173.767 | K12: =J12*(1+'Assumptions & Drivers'!$B$25) -> 100627.67
A13: Deferred Tax Liabilities [Net] | B13: 1039.33 | C13: 630.43 | D13: 533.63 | E13: 410.01 | F13: 167.11 | G13: =F13 -> 167.11 | H13: =G13 -> 167.11 | I13: =H13 -> 167.11 | J13: =I13 -> 167.11 | K13: =J13 -> 167.11
A14: Other Long Term Liabilities | B14: 21.27 | C14: 81.73 | D14: 618.02 | E14: 594.74 | F14: 36.82 | G14: =F14 -> 36.82 | H14: =G14 -> 36.82 | I14: =H14 -> 36.82 | J14: =I14 -> 36.82 | K14: =J14 -> 36.82
A15: Long Term Provisions | B15: 817.77 | C15: 869.99 | D15: 987.38 | E15: 1124.01 | F15: 832.48 | G15: =F15 -> 832.48 | H15: =G15 -> 832.48 | I15: =H15 -> 832.48 | J15: =I15 -> 832.48 | K15: =J15 -> 832.48
A16: Total Non-Current Liabilities | B16: =SUM(B12:B15) -> 65241.66 | C16: =SUM(C12:C15) -> 64719.1 | D16: =SUM(D12:D15) -> 60476.85 | E16: =SUM(E12:E15) -> 62149.52 | F16: =SUM(F12:F15) -> 69521.91 | G16: =SUM(G12:G15) -> 75000.75 | H16: =SUM(H12:H15) -> 80917.897 | I16: =SUM(I12:I15) -> 87308.416 | ... K16: =SUM(K12:K15) -> 101664.08
A17: CURRENT LIABILITIES
A18: Short Term Borrowings | B18: 68979.51 | C18: 65228.39 | D18: 65656.14 | E18: 78913.71 | F18: 91049.87 | G18: =F18*(1+'Assumptions & Drivers'!$B$25) -> 98333.86 | H18: =G18*(1+'Assumptions & Drivers'!$B$25) -> 106200.57 | I18: =H18*(1+'Assumptions & Drivers'!$B$25) -> 114696.61 | J18: =I18*(1+'Assumptions & Drivers'!$B$25) -> 123872.34 | K18: =J18*(1+'Assumptions & Drivers'!$B$25) -> 133782.13
A19: Trade Payables | B19: 51144.24 | C19: 49784.12 | D19: 53292.88 | E19: 52459.34 | F19: 69455.64 | G19: ='WC & PPE Schedule'!G8 -> 75439.502 | H19: ='WC & PPE Schedule'!H8 -> 84492.243 | I19: ='WC & PPE Schedule'!I8 -> 94631.312 | J19: ='WC & PPE Schedule'!J8 -> 105987.07 | K19: ='WC & PPE Schedule'!K8 -> 118705.52
A20: Other Current Liabilities | B20: 35953.92 | C20: 43560.01 | D20: 54194.2 | E20: 65906.18 | F20: 88982.98 | G20: =F20*(1+'Assumptions & Drivers'!$B$25) -> 96101.618 | H20: =G20*(1+'Assumptions & Drivers'!$B$25) -> 103789.75 | I20: =H20*(1+'Assumptions & Drivers'!$B$25) -> 112092.93 | J20: =I20*(1+'Assumptions & Drivers'!$B$25) -> 121060.36 | K20: =J20*(1+'Assumptions & Drivers'!$B$25) -> 130745.19
A21: Short Term Provisions | B21: 3355.86 | C21: 3493.47 | D21: 3457.51 | E21: 4691.67 | F21: 5009.03 | G21: =F21 -> 5009.03 | H21: =G21 -> 5009.03 | I21: =H21 -> 5009.03 | J21: =I21 -> 5009.03 | K21: =J21 -> 5009.03
A22: Suspense | G22: 7375.2 | H22: 7375.2 | I22: 7375.2 | J22: 7375.2 | K22: 16342.634
A23: Total Current Liabilities | B23: =SUM(B18:B21) -> 159433.53 | C23: =SUM(C18:C21) -> 162065.99 | D23: =SUM(D18:D21) -> 176600.73 | E23: =SUM(E18:E21) -> 201970.9 | F23: =SUM(F18:F21) -> 254497.52 | G23: =SUM(G18:G22) -> 282259.21 | H23: =SUM(H18:H22) -> 306866.79 | I23: =SUM(I18:I22) -> 333805.08 | J23: =SUM(J18:J22) -> 363304 | K23: =SUM(K18:K22) -> 404584.5
A24: TOTAL EQUITY & LIABILITIES | B24: =B10+B16+B23 -> 320048.92 | C24: =C10+C16+C23 -> 330352.31 | D24: =D10+D16+D23 -> 339627.24 | E24: =E10+E16+E23 -> 379524.1 | F24: =F10+F16+F23 -> 452549.89 | G24: =G10+G16+G23 -> 512920.11 | H24: =H10+H16+H23 -> 574338.82 | I24: =I10+I16+I23 -> 642719.05 | ... K24: =K10+K16+K23 -> 812355.71
A25: ASSETS
A26: NON-CURRENT ASSETS
A27: Tangible Assets (Net) | B27: 16530.47 | C27: 16834.37 | D27: 17778.42 | E27: 18656.21 | F27: 20557.16 | G27: ='WC & PPE Schedule'!G20*0.6601 -> 29230.832 | H27: ='WC & PPE Schedule'!H20*0.6601 -> 31698.257 | I27: ='WC & PPE Schedule'!I20*0.6601 -> 34753.049 | J27: ='WC & PPE Schedule'!J20*0.6601 -> 38384.136 | K27: ='WC & PPE Schedule'!K20*0.6601 -> 42601.952
A28: Intangible Assets | B28: 26285.58 | C28: 25923.11 | D28: 25333.37 | E28: 25597.06 | F28: 10584.45 | G28: ='WC & PPE Schedule'!G20*0.3399 -> 15051.598 | H28: ='WC & PPE Schedule'!H20*0.3399 -> 16322.129 | I28: ='WC & PPE Schedule'!I20*0.3399 -> 17895.109 | J28: ='WC & PPE Schedule'!J20*0.3399 -> 19764.835 | K28: ='WC & PPE Schedule'!K20*0.3399 -> 21936.681
A29: Capital Work-In-Progress | B29: 1170.32 | C29: 2949.09 | D29: 2897.04 | E29: 2390.86 | F29: 3036.25 | G29: =F29 -> 3036.25 | H29: =G29 -> 3036.25 | I29: =H29 -> 3036.25 | J29: =I29 -> 3036.25 | K29: =J29 -> 3036.25
A30: Total Fixed Assets | B30: =SUM(B27:B29) -> 43986.37 | C30: =SUM(C27:C29) -> 45706.57 | D30: =SUM(D27:D29) -> 46008.83 | E30: =SUM(E27:E29) -> 46644.13 | F30: =SUM(F27:F29) -> 34177.86 | G30: =SUM(G27:G29) -> 47318.68 | H30: =SUM(H27:H29) -> 51056.636 | I30: =SUM(I27:I29) -> 55684.408 | ... K30: =SUM(K27:K29) -> 67574.883
A31: Non-Current Investments | B31: 9810.86 | C31: 9224.89 | D31: 10690.19 | E31: 11444.65 | F31: 8851.93 | G31: =F31 -> 8851.93 | H31: =G31 -> 8851.93 | I31: =H31 -> 8851.93 | J31: =I31 -> 8851.93 | K31: =J31 -> 8851.93
A32: Deferred Tax Assets [Net] | B32: 2840.1 | C32: 3984.79 | D32: 3863.72 | E32: 3792.88 | F32: 4252.76 | G32: =F32 -> 4252.76 | H32: =G32 -> 4252.76 | I32: =H32 -> 4252.76 | J32: =I32 -> 4252.76 | K32: =J32 -> 4252.76
A33: Long Term Loans and Advances | B33: 49152.8 | C33: 43242.7 | D33: 54582.3 | E33: 65059.35 | F33: 79859.32 | G33: =F33*(1+'Assumptions & Drivers'!$B$25) -> 86248.066 | H33: =G33*(1+'Assumptions & Drivers'!$B$25) -> 93147.911 | I33: =H33*(1+'Assumptions & Drivers'!$B$25) -> 100599.74 | J33: =I33*(1+'Assumptions & Drivers'!$B$25) -> 108647.72 | K33: =J33*(1+'Assumptions & Drivers'!$B$25) -> 117339.54
A34: Other Non-Current Assets | B34: 6077.62 | C34: 5989.04 | D34: 6402.33 | E34: 7241.38 | F34: 7096.7 | G34: =F34 -> 7096.7 | H34: =G34 -> 7096.7 | I34: =H34 -> 7096.7 | J34: =I34 -> 7096.7 | K34: =J34 -> 7096.7
A35: Total Non-Current Assets | B35: =SUM(B30:B34) -> 111867.75 | C35: =SUM(C30:C34) -> 108147.99 | D35: =SUM(D30:D34) -> 121547.37 | E35: =SUM(E30:E34) -> 134182.39 | F35: =SUM(F30:F34) -> 134238.57 | G35: =SUM(G30:G34) -> 153768.14 | H35: =SUM(H30:H34) -> 164405.94 | I35: =SUM(I30:I34) -> 176485.54 | ... K35: =SUM(K30:K34) -> 205115.81
A36: CURRENT ASSETS
A37: Current Investments | B37: 29792.51 | C37: 35573.42 | D37: 34957.63 | E37: 43360.62 | F37: 59524.86 | G37: =F37 -> 59524.86 | H37: =G37 -> 59524.86 | I37: =H37 -> 59524.86 | J37: =I37 -> 59524.86 | K37: =J37 -> 59524.86
A38: Inventories | B38: 5943.32 | C38: 6828.78 | D38: 6620.19 | E38: 7670.55 | F38: 9530.93 | G38: ='WC & PPE Schedule'!G7 -> 10526.442 | H38: ='WC & PPE Schedule'!H7 -> 11789.615 | I38: ='WC & PPE Schedule'!I7 -> 13204.369 | J38: ='WC & PPE Schedule'!J7 -> 14788.893 | K38: ='WC & PPE Schedule'!K7 -> 16563.561
A39: Trade Receivables | B39: 46138.92 | C39: 44731.53 | D39: 48770.95 | E39: 53713.68 | F39: 60461.26 | G39: ='WC & PPE Schedule'!G6 -> 67544.671 | H39: ='WC & PPE Schedule'!H6 -> 75650.031 | I39: ='WC & PPE Schedule'!I6 -> 84728.035 | J39: ='WC & PPE Schedule'!J6 -> 94895.399 | K39: ='WC & PPE Schedule'!K6 -> 106282.85
A40: Cash and Cash Equivalents | B40: 18953.17 | C40: 22519.6 | D40: 15358.39 | E40: 22965.34 | F40: 20847.67 | G40: ='Cash Flow Statement'!G21 -> 40173.671 | H40: ='Cash Flow Statement'!H21 -> 67075.461 | I40: ='Cash Flow Statement'!I21 -> 97211.893 | J40: ='Cash Flow Statement'!J21 -> 131059.01 | K40: ='Cash Flow Statement'!K21 -> 178099.97
A41: Short Term Loans and Advances | B41: 46389.58 | C41: 45641.8 | D41: 40485.05 | E41: 41914.25 | F41: 51173.23 | G41: =F41*(1+'Assumptions & Drivers'!$B$25) -> 55267.088 | H41: =G41*(1+'Assumptions & Drivers'!$B$25) -> 59688.455 | I41: =H41*(1+'Assumptions & Drivers'!$B$25) -> 64463.532 | J41: =I41*(1+'Assumptions & Drivers'!$B$25) -> 69620.614 | K41: =J41*(1+'Assumptions & Drivers'!$B$25) -> 75190.264
...

Sheet Cash Flow Statement
A1: CONSOLIDATED CASH FLOW STATEMENT (INR Crores)
A3: Particulars | B3: FY22 | C3: FY23 | D3: FY24 | E3: FY25 | F3: FY26 | G3: FY27F | H3: FY28F | I3: FY29F | J3: FY30F | K3: FY31F
A4: A. CASH FLOW FROM OPERATING ACTIVITIES
A5: Profit Before Tax (from P&L) | B5: 14410.73 | C5: 17200.5 | D5: 20150.8 | E5: 23578.79 | F5: 25975.81 | G5: ='Income Statement'!G17 -> 60288.193 | H5: ='Income Statement'!H17 -> 68653.301 | I5: ='Income Statement'!I17 -> 77892.032 | J5: ='Income Statement'!J17 -> 88160.584 | K5: ='Income Statement'!K17 -> 99620.707
A6: Add: Depreciation & Amortisation | B6: 2947.95 | C6: 3502.4 | D6: 3810.5 | E6: 4121.18 | F6: 4364.75 | G6: ='Income Statement'!G12 -> 11617.808 | H6: ='Income Statement'!H12 -> 12399.08 | I6: ='Income Statement'!I12 -> 13445.708 | J6: ='Income Statement'!J12 -> 14741.484 | K6: ='Income Statement'!K12 -> 16281.712
A7: Less: Working Capital Changes (Net) | B7: -3060.93 | C7: -8016.59 | D7: 1710.2 | E7: 2712.11 | F7: -1774.14 | G7: ='WC & PPE Schedule'!G10 -> 2095.0505 | H7: ='WC & PPE Schedule'!H10 -> 315.79327 | I7: ='WC & PPE Schedule'!I10 -> 353.68846 | J7: ='WC & PPE Schedule'!J10 -> 396.13107 | K7: ='WC & PPE Schedule'!K10 -> 443.6668
A8: Less: Operating Expansion (Loans & Other Net Assets) | B8: 0 | C8: 0 | D8: 0 | E8: 0 | F8: 0 | G8: =('Balance Sheet'!G33-'Balance Sheet'!F33)+('Balance Sheet'!G41-'Balance Sheet'!F41)+('Balance Sheet'!G42-'Balance Sheet'!F42)-('Balance Sheet'!G20-'Balance Sheet'!F20) -> 12705.835 | H8: =('Balance Sheet'!H33-'Balance Sheet'!G33)+('Balance Sheet'!H41-'Balance Sheet'!G41)+('Balance Sheet'!H42-'Balance Sheet'!G42)-('Balance Sheet'!H20-'Balance Sheet'!G20) -> 13722.302 | I8: =('Balance Sheet'!I33-'Balance Sheet'!H33)+('Balance Sheet'!I41-'Balance Sheet'!H41)+('Balance Sheet'!I42-'Balance Sheet'!H42)-('Balance Sheet'!I20-'Balance Sheet'!H20) -> 14820.086 | J8: =('Balance Sheet'!J33-'Balance Sheet'!I33)+('Balance Sheet'!J41-'Balance Sheet'!I41)+('Balance Sheet'!J42-'Balance Sheet'!I42)-('Balance Sheet'!J20-'Balance Sheet'!I20) -> 16005.693 | K8: =('Balance Sheet'!K33-'Balance Sheet'!J33)+('Balance Sheet'!K41-'Balance Sheet'!J41)+('Balance Sheet'!K42-'Balance Sheet'!J42)-('Balance Sheet'!K20-'Balance Sheet'!I20) -> 8318.7143
A9: Less: Income Taxes Paid | B9: -4512.09 | C9: -4980.2 | D9: -5520.4 | E9: -6100.82 | F9: -6752.96 | G9: ='Income Statement'!G18 -> 15072.048 | H9: ='Income Statement'!H18 -> 17163.325 | I9: ='Income Statement'!I18 -> 19473.008 | J9: ='Income Statement'!J18 -> 22040.146 | K9: ='Income Statement'!K18 -> 24905.177
A10: Net Cash Flow from Operating Activities (CFO) | B10: 14297.75 | C10: 12686.31 | D10: 25671.5 | E10: 30412.08 | F10: 28566.42 | G10: =G5+G6-G7-G8-G9 -> 42033.067 | H10: =H5+H6-H7-H8-H9 -> 49850.961 | I10: =I5+I6-I7-I8-I9 -> 56690.958 | J10: =J5+J6-J7-J8-J9 -> 64460.098 | K10: =K5+K6-K7-K8-K9 -> 82234.861
A11: B. CASH FLOW FROM INVESTING ACTIVITIES
A12: Capital Expenditure | B12: -2150.4 | C12: -2850.6 | D12: -3450.8 | E12: -4120.5 | F12: -4850.6 | G12: =-'WC & PPE Schedule'!G18 -> -14408.068 | H12: =-'WC & PPE Schedule'!H18 -> -16137.036 | I12: =-'WC & PPE Schedule'!I18 -> -18073.48 | J12: =-'WC & PPE Schedule'!J18 -> -20242.298 | K12: =-'WC & PPE Schedule'!K18 -> -22671.374
A13: Net Cash Used in Investing Activities (CFI) | B13: 1400.8 | C13: -4837.8 | D13: -5419.4 | E13: -4460.11 | F13: -17343.74 | G13: =G12 -> -14408.068 | H13: =H12 -> -16137.036 | I13: =I12 -> -18073.48 | J13: =J12 -> -20242.298 | K13: =K12 -> -22671.374
A14: C. CASH FLOW FROM FINANCING ACTIVITIES
A15: Net Change in Borrowings | B15: -17631.6 | C15: -195.91 | D15: 500.2 | E15: 702.48 | F15: -10715.32 | G15: =('Balance Sheet'!G47-'Balance Sheet'!F47) -> 12762.83 | H15: =('Balance Sheet'!H47-'Balance Sheet'!G47) -> 13783.856 | I15: =('Balance Sheet'!I47-'Balance Sheet'!H47) -> 14886.564 | J15: =('Balance Sheet'!J47-'Balance Sheet'!I47) -> 16077.49 | K15: =('Balance Sheet'!K47-'Balance Sheet'!J47) -> 17363.689
A16: Dividend Paid | B16: -2520.4 | C16: -3080.5 | D16: -3920.6 | E16: -4900.2 | F16: -5600.4 | G16: =-'Income Statement'!G28 -> -18086.458 | H16: =-'Income Statement'!H28 -> -20595.99 | I16: =-'Income Statement'!I28 -> -23367.61 | J16: =-'Income Statement'!J28 -> -26448.175 | K16: =-'Income Statement'!K28 -> -29886.212
A17: Net Cash from Financing Activities (CFF) | B17: =B15+B16 -> -20152 | C17: =C15+C16 -> -3276.41 | D17: =D15+D16 -> -3420.4 | E17: =E15+E16 -> -4197.72 | F17: =F15+F16 -> -16315.72 | G17: =G15+G16 -> -5323.6284 | H17: =H15+H16 -> -6812.1343 | I17: =I15+I16 -> -8481.0452 | ... K17: =K15+K16 -> -12522.523
A18: D. NET CHANGE IN CASH
A19: Net Increase / (Decrease) in Cash | B19: =B10+B13+B17 -> -4453.45 | C19: =C10+C13+C17 -> 4572.1 | D19: =D10+D13+D17 -> 16831.7 | E19: =E10+E13+E17 -> 21754.25 | F19: =F10+F13+F17 -> -5093.04 | G19: =G10+G13+G17 -> 22301.371 | H19: =H10+H13+H17 -> 26901.791 | I19: =I10+I13+I17 -> 30136.432 | ... K19: =K10+K13+K17 -> 47040.964
A20: Cash at Beginning of Year | B20: 13373.52 | C20: 18953.17 | D20: 22519.6 | E20: 15358.39 | F20: 22965.34 | G20: =F21 -> 17872.3 | H20: =G21 -> 40173.671 | I20: =H21 -> 67075.461 | J20: =I21 -> 97211.893 | K20: =J21 -> 131059.01
A21: Cash at End of Year | B21: =B19+B20 -> 8920.07 | C21: =C19+C20 -> 23525.27 | D21: =D19+D20 -> 39351.3 | E21: =E19+E20 -> 37112.64 | F21: =F19+F20 -> 17872.3 | G21: =G19+G20 -> 40173.671 | H21: =H19+H20 -> 67075.461 | I21: =I19+I20 -> 97211.893 | ... K21: =K19+K20 -> 178099.97
A22: Memo: Free Cash Flow to Firm (CFO - Capex) | B22: =B10+B12 -> 12147.35 | C22: =C10+C12 -> 9835.71 | D22: =D10+D12 -> 22220.7 | E22: =E10+E12 -> 26291.58 | F22: =F10+F12 -> 23715.82 | G22: =G10+G12 -> 27624.999 | H22: =H10+H12 -> 33713.925 | I22: =I10+I12 -> 38617.477 | ... K22: =K10+K12 -> 59563.488

Sheet WC & PPE Schedule
A1: WORKING CAPITAL & PPE SCHEDULE (INR Crores)
A3: Particulars | B3: FY22 | C3: FY23 | D3: FY24 | E3: FY25 | F3: FY26 | G3: FY27F | H3: FY28F | I3: FY29F | J3: FY30F | K3: FY31F
A4: Revenue from Operations | B4: ='Income Statement'!B5 -> 156521.23 | C4: ='Income Statement'!C5 -> 183340.7 | D4: ='Income Statement'!D5 -> 221112.89 | E4: ='Income Statement'!E5 -> 255734.45 | F4: ='Income Statement'!F5 -> 285874.36 | G4: ='Income Statement'!G5 -> 320179.28 | H4: ='Income Statement'!H5 -> 358600.8 | I4: ='Income Statement'!I5 -> 401632.89 | ... K4: ='Income Statement'!K5 -> 503808.3
A5: WORKING CAPITAL SCHEDULE
A6: Trade Receivables | B6: 46138.92 | C6: 44731.53 | D6: 48770.95 | E6: 53713.68 | F6: 60461.26 | G6: =('Assumptions & Drivers'!$B$16/365)*'Income Statement'!G5 -> 67544.671 | H6: =('Assumptions & Drivers'!$B$16/365)*'Income Statement'!H5 -> 75650.031 | I6: =('Assumptions & Drivers'!$B$16/365)*'Income Statement'!I5 -> 84728.035 | J6: =('Assumptions & Drivers'!$B$16/365)*'Income Statement'!J5 -> 94895.399 | K6: =('Assumptions & Drivers'!$B$16/365)*'Income Statement'!K5 -> 106282.85
A7: Inventories | B7: 5943.32 | C7: 6828.78 | D7: 6620.19 | E7: 7670.55 | F7: 9530.93 | G7: =('Assumptions & Drivers'!$B$17/365)*'Income Statement'!G5 -> 10526.442 | H7: =('Assumptions & Drivers'!$B$17/365)*'Income Statement'!H5 -> 11789.615 | I7: =('Assumptions & Drivers'!$B$17/365)*'Income Statement'!I5 -> 13204.369 | J7: =('Assumptions & Drivers'!$B$17/365)*'Income Statement'!J5 -> 14788.893 | K7: =('Assumptions & Drivers'!$B$17/365)*'Income Statement'!K5 -> 16563.561
A8: Trade Payables | B8: 51144.24 | C8: 49784.12 | D8: 53292.88 | E8: 52459.34 | F8: 69455.63 | G8: =('Assumptions & Drivers'!$B$18/365)*'Income Statement'!G5 -> 75439.502 | H8: =('Assumptions & Drivers'!$B$18/365)*'Income Statement'!H5 -> 84492.243 | I8: =('Assumptions & Drivers'!$B$18/365)*'Income Statement'!I5 -> 94631.312 | J8: =('Assumptions & Drivers'!$B$18/365)*'Income Statement'!J5 -> 105987.07 | K8: =('Assumptions & Drivers'!$B$18/365)*'Income Statement'!K5 -> 118705.52
A9: Net Working Capital (Rec + Inv - Pay) | B9: =B6+B7-B8 -> 938 | C9: =C6+C7-C8 -> 1776.19 | D9: =D6+D7-D8 -> 2098.26 | E9: =E6+E7-E8 -> 8924.89 | F9: =F6+F7-F8 -> 536.56 | G9: =G6+G7-G8 -> 2631.6105 | H9: =H6+H7-H8 -> 2947.4038 | I9: =I6+I7-I8 -> 3301.0923 | ... K9: =K6+K7-K8 -> 4140.8901
A10: Change in Net Working Capital | B10: 0 | C10: =C9-B9 -> 838.19 | D10: =D9-C9 -> 322.07 | E10: =E9-D9 -> 6826.63 | F10: =F9-E9 -> -8388.33 | G10: =G9-F9 -> 2095.0505 | H10: =H9-G9 -> 315.79327 | I10: =I9-H9 -> 353.68846 | J10: =J9-I9 -> 396.13107 | K10: =K9-J9 -> 443.6668
A11: WORKING CAPITAL DAYS
A12: Receivable Days (365 x Rec / Rev) | B12: =B6/B4*365 -> 107.59375 | C12: =C6/C4*365 -> 89.052831 | D12: =D6/D4*365 -> 80.508182 | E12: =E6/E4*365 -> 76.663481 | F12: =F6/F4*365 -> 77.19601 | G12: ='Assumptions & Drivers'!$B$16 -> 77 | H12: ='Assumptions & Drivers'!$B$16 -> 77 | I12: ='Assumptions & Drivers'!$B$16 -> 77 | J12: ='Assumptions & Drivers'!$B$16 -> 77 | K12: ='Assumptions & Drivers'!$B$16 -> 77
A13: Inventory Days (365 x Inv / Rev) | B13: =B7/B4*365 -> 13.859537 | C13: =C7/C4*365 -> 13.594934 | D13: =D7/D4*365 -> 10.928216 | E13: =E7/E4*365 -> 10.947883 | F13: =F7/F4*365 -> 12.168945 | G13: ='Assumptions & Drivers'!$B$17 -> 12 | H13: ='Assumptions & Drivers'!$B$17 -> 12 | I13: ='Assumptions & Drivers'!$B$17 -> 12 | J13: ='Assumptions & Drivers'!$B$17 -> 12 | K13: ='Assumptions & Drivers'!$B$17 -> 12
A14: Payable Days (365 x Pay / Rev) | B14: =B8/B4*365 -> 119.26591 | C14: =C8/C4*365 -> 99.111675 | D14: =D8/D4*365 -> 87.972715 | E14: =E8/E4*365 -> 74.87321 | F14: =F8/F4*365 -> 88.679884 | G14: ='Assumptions & Drivers'!$B$18 -> 86 | H14: ='Assumptions & Drivers'!$B$18 -> 86 | I14: ='Assumptions & Drivers'!$B$18 -> 86 | J14: ='Assumptions & Drivers'!$B$18 -> 86 | K14: ='Assumptions & Drivers'!$B$18 -> 86
A15: Cash Conversion Cycle | B15: =B12+B13-B14 -> 2.187371 | C15: =C12+C13-C14 -> 3.5360907 | D15: =D12+D13-D14 -> 3.4636827 | E15: =E12+E13-E14 -> 12.738154 | F15: =F12+F13-F14 -> 0.68507158 | G15: =G12+G13-G14 -> 3 | H15: =H12+H13-H14 -> 3 | I15: =I12+I13-I14 -> 3 | ... K15: =K12+K13-K14 -> 3
A16: PPE SCHEDULE
A17: Opening Net PPE | B17: 42816.05 | C17: =B20 -> 42018.5 | D17: =C20 -> 41366.7 | E17: =D20 -> 41007 | F17: =E20 -> 41006.32 | G17: =F20 -> 41492.17 | H17: =G20 -> 44282.43 | I17: =H20 -> 48020.386 | J17: =I20 -> 52648.158 | K17: =J20 -> 58148.971
A18: Add: Capital Expenditure (Capex) | B18: 2150.4 | C18: 2850.6 | D18: 3450.8 | E18: 4120.5 | F18: 4850.6 | G18: ='Assumptions & Drivers'!$B$20*'Income Statement'!G5 -> 14408.068 | H18: ='Assumptions & Drivers'!$B$20*'Income Statement'!H5 -> 16137.036 | I18: ='Assumptions & Drivers'!$B$20*'Income Statement'!I5 -> 18073.48 | J18: ='Assumptions & Drivers'!$B$20*'Income Statement'!J5 -> 20242.298 | K18: ='Assumptions & Drivers'!$B$20*'Income Statement'!K5 -> 22671.374
A19: Less: Depreciation & Amortisation | B19: 2947.95 | C19: 3502.4 | D19: 3810.5 | E19: 4121.18 | F19: 4364.75 | G19: ='Assumptions & Drivers'!$B$21*G17 -> 11617.808 | H19: ='Assumptions & Drivers'!$B$21*H17 -> 12399.08 | I19: ='Assumptions & Drivers'!$B$21*I17 -> 13445.708 | J19: ='Assumptions & Drivers'!$B$21*J17 -> 14741.484 | K19: ='Assumptions & Drivers'!$B$21*K17 -> 16281.712
A20: Closing Net PPE | B20: =B17+B18-B19 -> 42018.5 | C20: =C17+C18-C19 -> 41366.7 | D20: =D17+D18-D19 -> 41007 | E20: =E17+E18-E19 -> 41006.32 | F20: =F17+F18-F19 -> 41492.17 | G20: =G17+G18-G19 -> 44282.43 | H20: =H17+H18-H19 -> 48020.386 | I20: =I17+I18-I19 -> 52648.158 | ... K20: =K17+K18-K19 -> 64538.633
A21: Capex as % of Revenue | B21: =B18/B4 -> 0.013738711 | C21: =C18/C4 -> 0.015548103 | D21: =D18/D4 -> 0.015606508 | E21: =E18/E4 -> 0.016112417 | F21: =F18/F4 -> 0.016967594 | G21: ='Assumptions & Drivers'!$B$20 -> 0.045 | H21: ='Assumptions & Drivers'!$B$20 -> 0.045 | I21: ='Assumptions & Drivers'!$B$20 -> 0.045 | J21: ='Assumptions & Drivers'!$B$20 -> 0.045 | K21: ='Assumptions & Drivers'!$B$20 -> 0.045
A22: Depreciation as % of Opening Net PPE | B22: =B19/B17 -> 0.068851517 | C22: =C19/C17 -> 0.083353761 | D22: =D19/D17 -> 0.092115155 | E22: =E19/E17 -> 0.10049943 | F22: =F19/F17 -> 0.10644091 | G22: ='Assumptions & Drivers'!$B$21 -> 0.28 | H22: ='Assumptions & Drivers'!$B$21 -> 0.28 | I22: ='Assumptions & Drivers'!$B$21 -> 0.28 | J22: ='Assumptions & Drivers'!$B$21 -> 0.28 | K22: ='Assumptions & Drivers'!$B$21 -> 0.28

Sheet Common-size & Trend
A1: COMMON-SIZE & TREND ANALYSIS
A3: A. COMMON-SIZE INCOME STATEMENT (% of Revenue from Operations)
A4: Particulars | B4: FY22 | C4: FY23 | D4: FY24 | E4: FY25 | F4: FY26
A5: Revenue from Operations | B5: ='Income Statement'!B5/'Income Statement'!B5 -> 1 | C5: ='Income Statement'!C5/'Income Statement'!C5 -> 1 | D5: ='Income Statement'!D5/'Income Statement'!D5 -> 1 | E5: ='Income Statement'!E5/'Income Statement'!E5 -> 1 | F5: ='Income Statement'!F5/'Income Statement'!F5 -> 1
A6: Operating and Direct Expenses | B6: ='Income Statement'!B9/'Income Statement'!B5 -> 0.52610128 | C6: ='Income Statement'!C9/'Income Statement'!C5 -> 0.54963682 | D6: ='Income Statement'!D9/'Income Statement'!D5 -> 0.53041819 | E6: ='Income Statement'!E9/'Income Statement'!E5 -> 0.53797953 | F6: ='Income Statement'!F9/'Income Statement'!F5 -> 0.53773556
A7: Employee Benefit Expenses | B7: ='Income Statement'!B10/'Income Statement'!B5 -> 0.18996484 | C7: ='Income Statement'!C10/'Income Statement'!C5 -> 0.19744879 | D7: ='Income Statement'!D10/'Income Statement'!D5 -> 0.18768965 | E7: ='Income Statement'!E10/'Income Statement'!E5 -> 0.18287986 | F7: ='Income Statement'!F10/'Income Statement'!F5 -> 0.18255299
A8: Finance Costs | B8: ='Income Statement'!B11/'Income Statement'!B5 -> 0.019969815 | C8: ='Income Statement'!C11/'Income Statement'!C5 -> 0.01745439 | D8: ='Income Statement'!D11/'Income Statement'!D5 -> 0.014700183 | E8: ='Income Statement'!E11/'Income Statement'!E5 -> 0.013038408 | F8: ='Income Statement'!F11/'Income Statement'!F5 -> 0.0099652868
A9: Depreciation and Amortisation | B9: ='Income Statement'!B12/'Income Statement'!B5 -> 0.018834186 | C9: ='Income Statement'!C12/'Income Statement'!C5 -> 0.019103232 | D9: ='Income Statement'!D12/'Income Statement'!D5 -> 0.017233278 | E9: ='Income Statement'!E12/'Income Statement'!E5 -> 0.016115076 | F9: ='Income Statement'!F12/'Income Statement'!F5 -> 0.015268071
A10: Other Expenses | B10: ='Income Statement'!B13/'Income Statement'!B5 -> 0.056426147 | C10: ='Income Statement'!C13/'Income Statement'!C5 -> 0.051544474 | D10: ='Income Statement'!D13/'Income Statement'!D5 -> 0.046131639 | E10: ='Income Statement'!E13/'Income Statement'!E5 -> 0.045195827 | F10: ='Income Statement'!F13/'Income Statement'!F5 -> 0.040925146
A11: Profit Before Tax | B11: ='Income Statement'!B17/'Income Statement'!B5 -> 0.2031879 | C11: ='Income Statement'!C17/'Income Statement'!C5 -> 0.18033983 | D11: ='Income Statement'!D17/'Income Statement'!D5 -> 0.21993928 | E11: ='Income Statement'!E17/'Income Statement'!E5 -> 0.22277714 | F11: ='Income Statement'!F17/'Income Statement'!F5 -> 0.22767887
A12: Consolidated PAT | B12: ='Income Statement'!B23/'Income Statement'!B5 -> 0.17506386 | C12: ='Income Statement'!C23/'Income Statement'!C5 -> 0.15407888 | D12: ='Income Statement'!D23/'Income Statement'!D5 -> 0.1958448 | E12: ='Income Statement'!E23/'Income Statement'!E5 -> 0.19979494 | F12: ='Income Statement'!F23/'Income Statement'!F5 -> 0.20455371
A14: B. COMMON-SIZE BALANCE SHEET (% of Total Assets)
A15: Particulars | B15: FY22 | C15: FY23 | D15: FY24 | E15: FY25 | F15: FY26
A16: Total Non-Current Assets | B16: ='Balance Sheet'!B35/'Balance Sheet'!B45 -> 0.34953328 | C16: ='Balance Sheet'!C35/'Balance Sheet'!C45 -> 0.32737168 | D16: ='Balance Sheet'!D35/'Balance Sheet'!D45 -> 0.35788463 | E16: ='Balance Sheet'!E35/'Balance Sheet'!E45 -> 0.35355433 | F16: ='Balance Sheet'!F35/'Balance Sheet'!F45 -> 0.29662712
A17: Total Current Assets | B17: ='Balance Sheet'!B44/'Balance Sheet'!B45 -> 0.65046672 | C17: ='Balance Sheet'!C44/'Balance Sheet'!C45 -> 0.67262832 | D17: ='Balance Sheet'!D44/'Balance Sheet'!D45 -> 0.64211537 | E17: ='Balance Sheet'!E44/'Balance Sheet'!E45 -> 0.64644567 | F17: ='Balance Sheet'!F44/'Balance Sheet'!F45 -> 0.70337288
A18: Inventories | B18: ='Balance Sheet'!B38/'Balance Sheet'!B45 -> 0.018570036 | C18: ='Balance Sheet'!C38/'Balance Sheet'!C45 -> 0.020671204 | D18: ='Balance Sheet'!D38/'Balance Sheet'!D45 -> 0.019492518 | E18: ='Balance Sheet'!E38/'Balance Sheet'!E45 -> 0.020210969 | F18: ='Balance Sheet'!F38/'Balance Sheet'!F45 -> 0.021060507
A19: Trade Receivables | B19: ='Balance Sheet'!B39/'Balance Sheet'!B45 -> 0.14416209 | C19: ='Balance Sheet'!C39/'Balance Sheet'!C45 -> 0.13540553 | D19: ='Balance Sheet'!D39/'Balance Sheet'!D45 -> 0.14360141 | E19: ='Balance Sheet'!E39/'Balance Sheet'!E45 -> 0.14152904 | F19: ='Balance Sheet'!F39/'Balance Sheet'!F45 -> 0.13360131
A20: Cash and Cash Equivalents | B20: ='Balance Sheet'!B40/'Balance Sheet'!B45 -> 0.059219603 | C20: ='Balance Sheet'!C40/'Balance Sheet'!C45 -> 0.068168435 | D20: ='Balance Sheet'!D40/'Balance Sheet'!D45 -> 0.045221314 | E20: ='Balance Sheet'!E40/'Balance Sheet'!E45 -> 0.060510887 | F20: ='Balance Sheet'!F40/'Balance Sheet'!F45 -> 0.04606712
A21: Total Equity | B21: ='Balance Sheet'!B10/'Balance Sheet'!B45 -> 0.29799735 | C21: ='Balance Sheet'!C10/'Balance Sheet'!C45 -> 0.31350536 | D21: ='Balance Sheet'!D10/'Balance Sheet'!D45 -> 0.30194769 | E21: ='Balance Sheet'!E10/'Balance Sheet'!E45 -> 0.30407471 | F21: ='Balance Sheet'!F10/'Balance Sheet'!F45 -> 0.2840139
A22: Total Non-Current Liabilities | B22: ='Balance Sheet'!B16/'Balance Sheet'!B45 -> 0.20384902 | C22: ='Balance Sheet'!C16/'Balance Sheet'!C45 -> 0.19590933 | D22: ='Balance Sheet'!D16/'Balance Sheet'!D45 -> 0.17806831 | E22: ='Balance Sheet'!E16/'Balance Sheet'!E45 -> 0.16375645 | F22: ='Balance Sheet'!F16/'Balance Sheet'!F45 -> 0.15362264
A23: Total Current Liabilities | B23: ='Balance Sheet'!B23/'Balance Sheet'!B45 -> 0.49815363 | C23: ='Balance Sheet'!C23/'Balance Sheet'!C45 -> 0.49058531 | D23: ='Balance Sheet'!D23/'Balance Sheet'!D45 -> 0.519984 | E23: ='Balance Sheet'!E23/'Balance Sheet'!E45 -> 0.53216884 | F23: ='Balance Sheet'!F23/'Balance Sheet'!F45 -> 0.56236346

Sheet Ratio Analysis
A1: FINANCIAL RATIO ANALYSIS
A3: Ratio Name | B3: Formula Used | C3: FY22 | D3: FY23 | E3: FY24 | F3: FY25 | G3: FY26 | H3: Financial Interpretation & Comments
A4: Current Ratio | B4: Current Assets / Current Liabilities | C4: ='Balance Sheet'!B44/'Balance Sheet'!B23 -> 1.3057553 | D4: ='Balance Sheet'!C44/'Balance Sheet'!C23 -> 1.3710731 | E4: ='Balance Sheet'!D44/'Balance Sheet'!D23 -> 1.2348752 | F4: ='Balance Sheet'!E44/'Balance Sheet'!E23 -> 1.2147379 | G4: ='Balance Sheet'!F44/'Balance Sheet'!F23 -> 1.2507443 | H4: Maintains a safe liquidity buffer (>1.2x) across all 5 years, reflecting strong short-term debt servicing capability.
A5: Quick Ratio | B5: (Cash + Investments + Receivables) / Current Liabilities | C5: =('Balance Sheet'!B37+'Balance Sheet'!B39+'Balance Sheet'!B40)/'Balance Sheet'!B23 -> 0.59513579 | D5: =('Balance Sheet'!C37+'Balance Sheet'!C39+'Balance Sheet'!C40)/'Balance Sheet'!C23 -> 0.634461 | E5: =('Balance Sheet'!D37+'Balance Sheet'!D39+'Balance Sheet'!D40)/'Balance Sheet'!D23 -> 0.56107905 | F5: =('Balance Sheet'!E37+'Balance Sheet'!E39+'Balance Sheet'!E40)/'Balance Sheet'!E23 -> 0.59434126 | G5: =('Balance Sheet'!F37+'Balance Sheet'!F39+'Balance Sheet'!F40)/'Balance Sheet'!F23 -> 0.55337981 | H5: Quick assets comfortably cover short-term liabilities, demonstrating robust liquidity without relying on inventory liquidation.
A6: Gross Profit Margin | B6: (Revenue - Operating Expenses) / Revenue | C6: =('Income Statement'!B5-'Income Statement'!B9)/'Income Statement'!B5 -> 0.47389872 | D6: =('Income Statement'!C5-'Income Statement'!C9)/'Income Statement'!C5 -> 0.45036318 | E6: =('Income Statement'!D5-'Income Statement'!D9)/'Income Statement'!D5 -> 0.46958181 | F6: =('Income Statement'!E5-'Income Statement'!E9)/'Income Statement'!E5 -> 0.46202047 | G6: =('Income Statement'!F5-'Income Statement'!F9)/'Income Statement'!F5 -> 0.46226444 | H6: High gross margin reflecting engineering value-add and subcontracting cost controls.
A7: EBITDA Margin | B7: (EBITDA) / Revenue | C7: ='Income Statement'!B24/'Income Statement'!B5 -> 0.22750773 | D7: ='Income Statement'!C24/'Income Statement'!C5 -> 0.20136991 | E7: ='Income Statement'!D24/'Income Statement'!D5 -> 0.23576052 | F7: ='Income Statement'!E24/'Income Statement'!E5 -> 0.23394478 | G7: ='Income Statement'!F24/'Income Statement'!F5 -> 0.2387863 | H7: Expanding EBITDA margin reaching ~24.0% driven by strong project execution and scale benefits.
A8: Operating Profit (EBIT) Margin | B8: EBIT / Revenue | C8: ='Income Statement'!B25/'Income Statement'!B5 -> 0.20867355 | D8: ='Income Statement'!C25/'Income Statement'!C5 -> 0.18226668 | E8: ='Income Statement'!D25/'Income Statement'!D5 -> 0.21852724 | F8: ='Income Statement'!E25/'Income Statement'!E5 -> 0.21782971 | G8: ='Income Statement'!F25/'Income Statement'!F5 -> 0.22351823 | H8: EBIT margins expanded consistently despite raw material inflation.
A9: Net Profit Margin | B9: Net Profit / Revenue | C9: ='Income Statement'!B23/'Income Statement'!B5 -> 0.17506386 | D9: ='Income Statement'!C23/'Income Statement'!C5 -> 0.15407888 | E9: ='Income Statement'!D23/'Income Statement'!D5 -> 0.1958448 | F9: ='Income Statement'!E23/'Income Statement'!E5 -> 0.19979494 | G9: ='Income Statement'!F23/'Income Statement'!F5 -> 0.20455371 | H9: Net margin improved due to operating leverage and higher IT/financial services contribution.
A10: Return on Assets (ROA) | B10: Net Profit / Total Assets | C10: ='Income Statement'!B23/'Balance Sheet'!B45 -> 0.085615693 | D10: ='Income Statement'!C23/'Balance Sheet'!C45 -> 0.085511526 | E10: ='Income Statement'!D23/'Balance Sheet'!D45 -> 0.12750394 | F10: ='Income Statement'!E23/'Balance Sheet'!E45 -> 0.13462768 | G10: ='Income Statement'!F23/'Balance Sheet'!F45 -> 0.12921594 | H10: ROA steadily increased showing efficient asset utilization across EPC and services.
A11: Return on Equity (ROE) | B11: Net Profit / Total Equity | C11: ='Income Statement'!B23/'Balance Sheet'!B10 -> 0.28730354 | D11: ='Income Statement'!C23/'Balance Sheet'!C10 -> 0.27275937 | E11: ='Income Statement'!D23/'Balance Sheet'!D10 -> 0.42227161 | F11: ='Income Statement'!E23/'Balance Sheet'!E10 -> 0.44274541 | G11: ='Income Statement'!F23/'Balance Sheet'!F10 -> 0.45496344 | H11: ROE expanded driven by higher profitability and capital return programs.
A12: Return on Capital Employed (ROCE) | B12: EBIT / (Total Equity + Total Debt) | C12: ='Income Statement'!B25/('Balance Sheet'!B10+'Balance Sheet'!B47) -> 0.14343201 | D12: ='Income Statement'!C25/('Balance Sheet'!C10+'Balance Sheet'!C47) -> 0.14408024 | E12: ='Income Statement'!D25/('Balance Sheet'!D10+'Balance Sheet'!D47) -> 0.21328868 | F12: ='Income Statement'!E25/('Balance Sheet'!E10+'Balance Sheet'!E47) -> 0.21902558 | G12: ='Income Statement'!F25/('Balance Sheet'!F10+'Balance Sheet'!F47) -> 0.2218178 | H12: ROCE improved, signaling strong return on long-term capital investments.
A13: Inventory Turnover | B13: Revenue / Inventories | C13: ='Income Statement'!B5/'Balance Sheet'!B38 -> 26.335656 | D13: ='Income Statement'!C5/'Balance Sheet'!C38 -> 26.848236 | E13: ='Income Statement'!D5/'Balance Sheet'!D38 -> 33.39978 | F13: ='Income Statement'!E5/'Balance Sheet'!E38 -> 33.33978 | G13: ='Income Statement'!F5/'Balance Sheet'!F38 -> 29.994382 | H13: Inventory turnover maintained showcasing lean inventory management in large turnkey projects.
A14: Debtors Turnover | B14: Revenue / Trade Receivables | C14: ='Income Statement'!B5/'Balance Sheet'!B39 -> 3.3923904 | D14: ='Income Statement'!C5/'Balance Sheet'!C39 -> 4.0986906 | E14: ='Income Statement'!D5/'Balance Sheet'!D39 -> 4.5337007 | F14: ='Income Statement'!E5/'Balance Sheet'!E39 -> 4.7610674 | G14: ='Income Statement'!F5/'Balance Sheet'!F39 -> 4.7282237 | H14: Receivables turnover improved indicating faster milestone billings.
A15: Asset Turnover | B15: Revenue / Total Assets | C15: ='Income Statement'!B5/'Balance Sheet'!B45 -> 0.48905408 | D15: ='Income Statement'!C5/'Balance Sheet'!C45 -> 0.55498537 | E15: ='Income Statement'!D5/'Balance Sheet'!D45 -> 0.65104581 | F15: ='Income Statement'!E5/'Balance Sheet'!E45 -> 0.67382928 | G15: ='Income Statement'!F5/'Balance Sheet'!F45 -> 0.63169689 | H15: Asset turnover ratio typical for capital-intensive infrastructure conglomerates.
A16: Debt-to-Equity Ratio | B16: Total Debt / Total Equity | C16: ='Balance Sheet'!B47/'Balance Sheet'!B10 -> 1.3876232 | D16: ='Balance Sheet'!C47/'Balance Sheet'!C10 -> 1.2394399 | E16: ='Balance Sheet'!D47/'Balance Sheet'!D10 -> 1.2091114 | F16: ='Balance Sheet'!E47/'Balance Sheet'!E10 -> 1.2038998 | G16: ='Balance Sheet'!F47/'Balance Sheet'!F10 -> 1.2412262 | H16: Total D/E maintained comfortably, supported by cash generation and capital strength.
A17: Interest Coverage Ratio | B17: EBIT / Finance Costs | C17: ='Income Statement'!B25/'Income Statement'!B11 -> 10.449448 | D17: ='Income Statement'!C25/'Income Statement'!C11 -> 10.442455 | E17: ='Income Statement'!D25/'Income Statement'!D11 -> 14.865613 | F17: ='Income Statement'!E25/'Income Statement'!E11 -> 16.706772 | G17: ='Income Statement'!F25/'Income Statement'!F11 -> 22.429683 | H17: Interest coverage expanded ensuring comfortable debt service capacity.
A18: Earnings Per Share (EPS) | B18: Net Profit / Shares | C18: ='Income Statement'!B26 -> 60.45 | D18: ='Income Statement'!C26 -> 74.5 | E18: ='Income Statement'!D26 -> 92.8 | F18: ='Income Statement'!E26 -> 124.5 | G18: ='Income Statement'!F26 -> 137.8 | H18: Consolidated EPS surged from Rs. 60.45 in FY22 to Rs. 137.80 in FY26.
A19: Book Value per Share (BVPS) | B19: Total Equity / Shares | C19: ='Balance Sheet'!B10/'Cover & Summary'!$B$10 -> 346.64969 | D19: ='Balance Sheet'!C10/'Cover & Summary'!$B$10 -> 376.43012 | E19: ='Balance Sheet'!D10/'Cover & Summary'!$B$10 -> 372.73165 | F19: ='Balance Sheet'!E10/'Cover & Summary'!$B$10 -> 419.45146 | G19: ='Balance Sheet'!F10/'Cover & Summary'!$B$10 -> 467.16265 | H19: BVPS grew consistently per share.

Sheet Beta Calculation
A1: BETA REGRESSION ANALYSIS (L&T vs NIFTY 50)
A3: Weekly Return Data (Last 52 Weeks) | G3: Regression Output | J3: Rationale & Methodology
A4: Date | B4: L&T Close (INR) | C4: L&T Weekly Return (%) | D4: Nifty Close (Points) | E4: Nifty Weekly Return (%) | G4: Metric | H4: Value | J4: Notes & Explanations
A5: 2025-04-04 | B5: 3260.15 | C5: - | D5: 22904.45 | E5: - | G5: Beta (SLOPE) | H5: =SLOPE(C6:C57, E6:E57) -> 1.1954336 | J5: Data Source: L&T NSE equity weekly prices & NIFTY 50 benchmark index from LT_Nifty_Merged_Historical_Data.xlsx
A6: 2025-04-11 | B6: 3115.95 | C6: =(B6-B5)/B5 -> -0.044231094 | D6: 22828.55 | E6: =(D6-D5)/D5 -> -0.0033137665 | G6: Alpha (Intercept) | H6: =INTERCEPT(C6:C57, E6:E57) -> 0.0023392546 | J6: Frequency: Weekly Friday closing prices to eliminate bid-ask noise and day-of-the-week effects.
A7: 2025-04-18 | B7: 3247.3 | C7: =(B7-B6)/B6 -> 0.042154078 | D7: 23851.65 | E7: =(D7-D6)/D6 -> 0.044816688 | G7: R-Squared (R²) | H7: =CORREL(C6:C57, E6:E57)^2 -> 0.3887139 | J7: Horizon: 52 weekly return pairs over the most recent 1-year trading window.
A8: 2025-04-25 | B8: 3272.1 | C8: =(B8-B7)/B7 -> 0.0076371139 | D8: 24039.35 | E8: =(D8-D7)/D7 -> 0.0078694765 | G8: Correlation (r) | H8: =CORREL(C6:C57, E6:E57) -> 0.62346925 | J8: Return Formula: Rt = (Pt - Pt-1) / Pt-1 arithmetic simple returns.
A9: 2025-05-02 | B9: 3329.8 | C9: =(B9-B8)/B8 -> 0.017633935 | D9: 24346.7 | E9: =(D9-D8)/D8 -> 0.012785287 | G9: Observations (n) | H9: =COUNT(C6:C57) -> 52 | J9: Blume Adjustment: Beta_adj = (1/3)*1.00 + (2/3)*Beta_raw.
A10: 2025-05-09 | B10: 3443.9 | C10: =(B10-B9)/B9 -> 0.034266322 | D10: 24008 | E10: =(D10-D9)/D9 -> -0.013911536 | G10: Avg L&T Weekly Return | H10: =AVERAGE(C6:C57) -> 0.0019269491 | J10: Mean-reversion ensures forward-looking stability for CAPM WACC.
A11: 2025-05-16 | B11: 3604.7 | C11: =(B11-B10)/B10 -> 0.046691251 | D11: 25019.8 | E11: =(D11-D10)/D10 -> 0.042144285 | G11: Avg Nifty Weekly Return | H11: =AVERAGE(E6:E57) -> -0.00034490043 | J11: Target Company: Larsen & Toubro Limited (NSE: LT).
A12: 2025-05-23 | B12: 3599.9 | C12: =(B12-B11)/B11 -> -0.0013315949 | D12: 24853.15 | E12: =(D12-D11)/D11 -> -0.0066607247 | G12: Std Dev - L&T | H12: =STDEV(C6:C57) -> 0.032618616 | J12: Benchmark Index: NIFTY 50 Index (^NSEI).
A13: 2025-05-30 | B13: 3675.1 | C13: =(B13-B12)/B12 -> 0.020889469 | D13: 24750.7 | E13: =(D13-D12)/D12 -> -0.0041222139 | G13: Std Dev - Nifty | H13: =STDEV(E6:E57) -> 0.01701199 | J13: Effective Beta feeds directly into Capital Structure & WACC Tab.
A14: 2025-06-06 | B14: 3656.3 | C14: =(B14-B13)/B13 -> -0.0051155071 | D14: 25003.05 | E14: =(D14-D13)/D13 -> 0.010195671 | G14: Raw Regression Beta | H14: =H5 -> 1.1954336
A15: 2025-06-13 | B15: 3587.4 | C15: =(B15-B14)/B14 -> -0.018844187 | D15: 24718.6 | E15: =(D15-D14)/D14 -> -0.011376612 | G15: Blume Adjusted Beta | H15: =1/3 + 2/3*H14 -> 1.1302891 | J15: Formula: =1/3 + (2/3)*Raw_Beta
A16: 2025-06-20 | B16: 3662 | C16: =(B16-B15)/B15 -> 0.020795005 | D16: 25112.4 | E16: =(D16-D15)/D15 -> 0.015931323 | G16: Effective Beta Used | H16: =H15 -> 1.1302891 | J16: Linked to Cost of Equity (CAPM)
A17: 2025-06-27 | B17: 3679.2 | C17: =(B17-B16)/B16 -> 0.0046968869 | D17: 25637.8 | E17: =(D17-D16)/D16 -> 0.020921935
A18: 2025-07-04 | B18: 3594.6 | C18: =(B18-B17)/B17 -> -0.022994129 | D18: 25461 | E18: =(D18-D17)/D17 -> -0.0068960675
A19: 2025-07-11 | B19: 3540.6 | C19: =(B19-B18)/B18 -> -0.015022534 | D19: 25149.85 | E19: =(D19-D18)/D18 -> -0.012220651
A20: 2025-07-18 | B20: 3464.8 | C20: =(B20-B19)/B19 -> -0.021408801 | D20: 24968.4 | E20: =(D20-D19)/D19 -> -0.0072147548
A21: 2025-07-25 | B21: 3442.9 | C21: =(B21-B20)/B20 -> -0.0063207112 | D21: 24837 | E21: =(D21-D20)/D20 -> -0.005262652
A22: 2025-08-01 | B22: 3587.3 | C22: =(B22-B21)/B21 -> 0.041941387 | D22: 24565.35 | E22: =(D22-D21)/D21 -> -0.010937311
A23: 2025-08-08 | B23: 3607.6 | C23: =(B23-B22)/B22 -> 0.0056588521 | D23: 24363.3 | E23: =(D23-D22)/D22 -> -0.0082249998
A24: 2025-08-15 | B24: 3677 | C24: =(B24-B23)/B23 -> 0.019237166 | D24: 24631.3 | E24: =(D24-D23)/D23 -> 0.011000152
A25: 2025-08-22 | B25: 3595.8 | C25: =(B25-B24)/B24 -> -0.02208322 | D25: 24870.1 | E25: =(D25-D24)/D24 -> 0.0096949816
A26: 2025-08-29 | B26: 3601 | C26: =(B26-B25)/B25 -> 0.0014461316 | D26: 24426.85 | E26: =(D26-D25)/D25 -> -0.017822606
A27: 2025-09-05 | B27: 3553.6 | C27: =(B27-B26)/B26 -> -0.01316301 | D27: 24741 | E27: =(D27-D26)/D26 -> 0.012860848
A28: 2025-09-12 | B28: 3579.8 | C28: =(B28-B27)/B27 -> 0.007372805 | D28: 25114 | E28: =(D28-D27)/D27 -> 0.015076189
... A57: 2026-04-03 | B57: 3504.1 | C57: =(B57-B56)/B56 -> -0.016834544 | D57: 22331.4 | E57: =(D57-D56)/D56 -> -0.021393889

Sheet Capital Structure & WACC
A1: CAPITAL STRUCTURE & WEIGHTED AVERAGE COST OF CAPITAL (WACC)
A3: 1. COST OF EQUITY (CAPM MODEL)
A4: Parameter | B4: Value | C4: Source / Formula
A5: Risk-Free Rate (Rf) | B5: ='Assumptions & Drivers'!$B$28 -> 0.071 | C5: 10-Year GOI Bond Yield
A6: Beta (Beta) | B6: ='Beta Calculation'!H16 -> 1.1302891 | C6: Blume Adjusted Beta from Beta Calculation Tab
A7: Equity Risk Premium (ERP) | B7: ='Assumptions & Drivers'!$B$29 -> 0.06 | C7: India Market Risk Premium
A8: Cost of Equity (Ke) | B8: =B5+B6*B7 -> 0.13881734 | C8: CAPM: Ke = Rf + Beta * ERP
A10: 2. COST OF DEBT & CAPITAL WEIGHTS
A11: Parameter | B11: Value | C11: Source / Formula
A12: Pre-Tax Cost of Debt (Kd) | B12: ='Assumptions & Drivers'!$B$26 -> 0.078 | C12: Weighted average pre-tax cost of borrowing
A13: Marginal Tax Rate (t) | B13: ='Assumptions & Drivers'!$B$14 -> 0.2517 | C13: Corporate statutory tax rate
A14: After-Tax Cost of Debt [Kd*(1-t)] | B14: =B12*(1-B13) -> 0.0583674 | C14: Kd * (1 - Tax Rate)
A15: Market Capitalization (Rs. Cr) | B15: ='Cover & Summary'!B11 -> 990468 | C15: Shares Outstanding * Market Price
A16: Total Debt (Rs. Cr) | B16: ='Balance Sheet'!F47 -> 159535.37 | C16: FY26 Total Borrowings
A17: Total Capitalization (Rs. Cr) | B17: =B15+B16 -> 1150003.4 | C17: Market Cap + Debt
A18: Weight of Equity (We) | B18: =B15/B17 -> 0.861274 | C18: Market Cap / Total Capital
A19: Weight of Debt (Wd) | B19: =B16/B17 -> 0.138726 | C19: Total Debt / Total Capital
A20: WEIGHTED AVERAGE COST OF CAPITAL (WACC) | B20: =B18*B8+B19*B14 -> 0.12765684 | C20: WACC = We*Ke + Wd*Kd*(1-t)

Sheet DCF Valuation
A1: DISCOUNTED CASH FLOW (DCF) VALUATION
A3: 1. FREE CASH FLOW TO FIRM (FCFF) PROJECTION (INR Crores)
A4: Particulars | B4: FY27F | C4: FY28F | D4: FY29F | E4: FY30F | F4: FY31F
A5: EBIT | B5: ='Income Statement'!G25 -> 66826.117 | C5: ='Income Statement'!H25 -> 75458.115 | D5: ='Income Statement'!I25 -> 84954.351 | E5: ='Income Statement'!J25 -> 95466.582 | F5: ='Income Statement'!K25 -> 107151.32
A6: Less: Tax on EBIT [EBIT * t] | B6: =B5*'Assumptions & Drivers'!$B$14 -> 16820.134 | C6: =C5*'Assumptions & Drivers'!$B$14 -> 18992.808 | D6: =D5*'Assumptions & Drivers'!$B$14 -> 21383.01 | E6: =E5*'Assumptions & Drivers'!$B$14 -> 24028.939 | F6: =F5*'Assumptions & Drivers'!$B$14 -> 26969.988
A7: NOPAT [EBIT*(1-t)] | B7: =B5-B6 -> 50005.983 | C7: =C5-C6 -> 56465.307 | D7: =D5-D6 -> 63571.341 | E7: =E5-E6 -> 71437.643 | F7: =F5-F6 -> 80181.334
A8: Add: Depreciation & Amortisation | B8: ='Income Statement'!G12 -> 11617.808 | C8: ='Income Statement'!H12 -> 12399.08 | D8: ='Income Statement'!I12 -> 13445.708 | E8: ='Income Statement'!J12 -> 14741.484 | F8: ='Income Statement'!K12 -> 16281.712
A9: Less: Capital Expenditure (Capex) | B9: ='WC & PPE Schedule'!G18 -> 14408.068 | C9: ='WC & PPE Schedule'!H18 -> 16137.036 | D9: ='WC & PPE Schedule'!I18 -> 18073.48 | E9: ='WC & PPE Schedule'!J18 -> 20242.298 | F9: ='WC & PPE Schedule'!K18 -> 22671.374
A10: Less: Change in Net Working Capital | B10: ='WC & PPE Schedule'!G10 -> 2095.0505 | C10: ='WC & PPE Schedule'!H10 -> 315.79327 | D10: ='WC & PPE Schedule'!I10 -> 353.68846 | E10: ='WC & PPE Schedule'!J10 -> 396.13107 | F10: ='WC & PPE Schedule'!K10 -> 443.6668
A11: Free Cash Flow to Firm (FCFF) | B11: =B7+B8-B9-B10 -> 45120.672 | C11: =C7+C8-C9-C10 -> 52411.559 | D11: =D7+D8-D9-D10 -> 58589.88 | E11: =E7+E8-E9-E10 -> 65540.698 | F11: =F7+F8-F9-F10 -> 73348.006
A12: Discount Period (Years) | B12: 1 | C12: 2 | D12: 3 | E12: 4 | F12: 5
A13: Discount Factor [1 / (1 + WACC)^t] | B13: =1/(1+'Capital Structure & WACC'!$B$20)^B12 -> 0.8867946 | C13: =1/(1+'Capital Structure & WACC'!$B$20)^C12 -> 0.78640466 | D13: =1/(1+'Capital Structure & WACC'!$B$20)^D12 -> 0.69737941 | E13: =1/(1+'Capital Structure & WACC'!$B$20)^E12 -> 0.61843229 | F13: =1/(1+'Capital Structure & WACC'!$B$20)^F12 -> 0.54842242
A14: Present Value of FCFF | B14: =B11*B13 -> 40012.769 | C14: =C11*C13 -> 41216.694 | D14: =D11*D13 -> 40859.376 | E14: =E11*E13 -> 40532.484 | F14: =F11*F13 -> 40225.691
A16: 2. VALUATION SUMMARY & PER SHARE INTRINSIC VALUE (INR Crores) | H16: Chart Data — Waterfall Bridge (auto-calculated from Section 2 above; do not edit)
A17: Component | B17: Amount (Rs. Cr) | C17: Formula / Source | H17: Step | I17: Base (invisible) | J17: Rise | K17: Fall
A18: Cumulative PV of Explicit FCFF (FY27F-FY31F) | B18: =SUM(B14:F14) -> 202847.01 | C18: Sum of PV of explicit FCFF | H18: Cumulative PV of FCFF (FY27F-FY31F) | I18: 0 | J18: =B18 -> 202847.01 | K18: 0
A19: Terminal Value (Perpetuity Method) | B19: =F11*(1+'Assumptions & Drivers'!$B$31)/('Capital Structure & WACC'!$B$20-'Assumptions & Drivers'!$B$31) -> 991740.09 | C19: FCFF_5 * (1+g) / (WACC - g) | H19: PV of Terminal Value | I19: =B18 -> 202847.01 | J19: =B20 -> 543892.5 | K19: 0
A20: Present Value of Terminal Value | B20: =B19*F13 -> 543892.5 | C20: Terminal Value discounted to PV | H20: Enterprise Value (EV) | I20: 0 | J20: =B21 -> 746739.51 | K20: 0
A21: ENTERPRISE VALUE (EV) | B21: =B18+B20 -> 746739.51 | C21: Cumulative PV of FCFF + PV of Terminal Value | H21: Less: Total Debt | I21: =B21-B22 -> 587204.14 | J21: 0 | K21: =B22 -> 159535.37
A22: Less: Total Debt (FY26) | B22: ='Balance Sheet'!F47 -> 159535.37 | C22: FY26 Total Borrowings | H22: Add: Cash & Equivalents | I22: =B21-B22 -> 587204.14 | J22: =B23 -> 80372.53 | K22: 0
A23: Add: Cash and Cash Equivalents (FY26) | B23: ='Balance Sheet'!F48 -> 80372.53 | C23: FY26 Cash & Current Investments | H23: Equity Value | I23: 0 | J23: =B24 -> 667576.67 | K23: 0
A24: EQUITY VALUE | B24: =B21-B22+B23 -> 667576.67 | C24: Enterprise Value - Debt + Cash
A25: Shares Outstanding (Crores) | B25: ='Cover & Summary'!B10 -> 275.13 | C25: Shares Outstanding
A26: INTRINSIC VALUE PER SHARE (Rs.) | B26: =B24/B25 -> 2426.4045 | C26: Equity Value / Shares Outstanding
A27: Current Market Price (Rs.) | B27: ='Cover & Summary'!B9 -> 3600 | C27: Current Trading Share Price
